inputFOK.txt
SUB LO B N1Eh 300 12
SUB LO B 0Gxb 250 11
SUB LO S JSvU 350 14
SUB LO S uH6w 320 15
SUB IOC S ckMR 150 10
SUB IOC B DVeP 500 14
SUB FOK S ejnR 200 12
SUB FOK S 8uGs 200 9
SUB LO B 2va9 250 12
SUB LO B 9zS1 300 11
CRP 2va9 480 11
CRP 9zS1 170 11
END
